Workbook

Sheet ENERO
B2: Cobranza Total 2025 | D2: =SUM(S2+S3+S4+S5+S6+S7+S8+S9+S10+S11+S12+D5+S13) -> 623596.23 | E2: Saldos 2024 | S2: =G214 -> 45163.987
E3: Enero`25 | S3: =H214 -> 0
B4: COBRANZA ENERO 2025 | E4: Febrero´25 | S4: =I214 -> 0
B5: Enero'2025 | D5: =S214+T214+U214 -> 578432.24 | E5: Marzo'25 | S5: =J214 -> 0
B6: Recuperación del 01 al 05 | D6: =SUM(V214:Z214) -> 7187 | E6: Abril´25 | S6: =K214 -> 0
B7: Recuperación del 06 al 12 | D7: =SUM(AA214:AG214) -> 155765.9 | E7: Mayo´25 | S7: =L214 -> 0
B8: Recuperación del 13 al 19 | D8: =SUM(AH214:AN214) -> 258118.96 | E8: Junio´25 | S8: =M214 -> 0
B9: Recuperación del 20 al 26 | D9: =SUM(AO214:AU214) -> 92161.09 | E9: Julio´25 | S9: =N214 -> 0
B10: Recuperación del 27 al 31 | D10: =SUM(AV214:AZ214) -> 55053.97 | E10: Agosto'25 | S10: =O214 -> 0
E11: Septiembre'25 | S11: =P214 -> 0
E12: Octubre'25 | S12: =Q214 -> 0
B13: Total Recuperado | D13: =SUM(D6:D11) -> 568286.92 | E13: Noviembre'25 | S13: =R214 -> 0
B14: Por Recuperar | D14: =D2-D13 -> 55309.31 | E14: Total de Arrastre: | S14: =SUM(S2:S13) -> 45163.987
A16: NO. | B16: CLIENTE | C16: DATOS FISCALES | D16: CONTACTO | E16: UNI | F16: VENTA | G16: ATRASO | S16: IMPORTE ENE´2025 | T16: SERV. EXTRAS | U16: DES % | V16: 1 | W16: 2 | X16: 3 | Y16: 4 | Z16: 5 | AA16: 6 | AB16: 7 | AC16: 8 | AD16: 9 | AE16: 10 | AF16: 11 | AG16: 12 | AH16: 13 | AI16: 14 | AJ16: 15 | AK16: 16 | AL16: 17 | AM16: 18 | AN16: 19 | AO16: 20 | AP16: 21 | AQ16: 22 | AR16: 23 | AS16: 24 | AT16: 25 | AU16: 26 | AV16: 27 | AW16: 28 | AX16: 29 | AY16: 30 | AZ16: 31 | BA16: SALDOS PENDIENTES | BB16: COMENTARIOS | BC16: ESTATUS PROMESA DE PAGO
G17: 2024 | H17: ENE | I17: FEB | J17: MAR | K17: ABR | L17: MAY | M17: JUN | N17: JUL | O17: AGO | P17: SEP | Q17: OCT | R17: NOV | V17: M | W17: J | X17: V | Y17: S | Z17: D | AA17: L | AB17: M | AC17: M | AD17: J | AE17: V | AF17: S | AG17: D | AH17: L | AI17: M | AJ17: M | AK17: J | AL17: V | AM17: S | AN17: D | AO17: L | AP17: M | AQ17: M | AR17: J | AS17: V | AT17: S | AU17: D | AV17: L | AW17: M | AX17: M | AY17: J | AZ17: V
A18: 1 | B18: ADRIANA ORANDAY DAVILA - RODRIGO ALANIS | D18: Rodrigo Alanis - 81 2861 1509 Email:adrianaoranday@gmail.com alanis_rodrigo@hotmail.com | E18: 1 | F18: JOSE LUIS | G18: =[1]DICIEMBRE!$BA$91 -> 290 | S18: =(250*0.16+250)*E18 -> 290 | BA18: =SUM(G18+S18+T18-U18-V18-W18-X18-Y18-Z18-AA18-AB18-AC18-AD18-AE18-AF18-AG18-AH18-AI18-AJ18-AK18-AL18-AM18-AN18-AO18-AP18-AQ18-AR18-AS18-AT18-AU18-AV18-AW18-AX18-AY18-AZ18) -> 580
A19: 2 | B19: ALIMENTOS REGIOMONTANOS PERCAM - ALIMENTOS GRUPER | C19: Nombre de la Empresa: ALIMENTOS GUPER S.A. DE C.V. Contacto: Nancy Paola Perales Teléfono: 811 801 4266 Email: alimentosgupersacv@gmail.com | D19: Alejandro Garcia - 81 2034 3938 Nancy Paola Perales - 8118014266 Alimentosregiopercam@gmail.com alimentosgupersacv@gmail.com | E19: 20 | F19: DANIEL ESTRADA | G19: =[1]DICIEMBRE!$BA$21 -> -0.3952 | S19: =(300*0.16+300)*E19 -> 6960 | T19: =1500*0.16+1500 -> 1740 | AH19: 8700 | BA19: =SUM(G19+S19+T19-U19-V19-W19-X19-Y19-Z19-AA19-AB19-AC19-AD19-AE19-AF19-AG19-AH19-AI19-AJ19-AK19-AL19-AM19-AN19-AO19-AP19-AQ19-AR19-AS19-AT19-AU19-AV19-AW19-AX19-AY19-AZ19) -> -0.3952 | BB19: COB. ENE'25: 1 REVISION Y 2 RE-INST.
A20: 3 | B20: AUTO EXPRESS GERAL 21 S.A. DE C.V. - LUIS GERARDO BOLAÑOS GARCIA | C20: Nombre de la Empresa: LUIS GERARDO BOLAÑOS GARCIA RFC. BOGL8702094H5 CFDI: Gastos en general Forma de Pago: Transferencia Teléfono: 811 027 0226 Contacto: Luis Gerardo Bolaños García Email: luismty0902@gmail.com; | D20: Luis Gerardo Bolaños García - 811 027 0226 Email:expressgeral19@gmail.com luismty0902@gmail.com | E20: 5 | F20: JOSE LUIS | G20: =[1]DICIEMBRE!$BA$75 -> 3190.0028 | S20: =(280*0.16+280)*E20 -> 1624 | T20: =450*0.16+450 -> 522 | AW20: 5336 | BA20: =SUM(G20+S20+T20-U20-V20-W20-X20-Y20-Z20-AA20-AB20-AC20-AD20-AE20-AF20-AG20-AH20-AI20-AJ20-AK20-AL20-AM20-AN20-AO20-AP20-AQ20-AR20-AS20-AT20-AU20-AV20-AW20-AX20-AY20-AZ20) -> 0.0028 | BB20: COB. ENE'25: 1 REVISION
A21: 4 | B21: AUTOEXPRESS MATA | C21: Nombre de la Empresa: AUTOEXPRESS MATA S.A. DE C.V. RFC. AMA040520BZ2 CFDI : Forma de Pago: Transferencia Teléfono: 81 1029 1017 Contacto: Edgar Garza Email: | D21: COMODATO Edgar Garza - 81 1029 1017 | E21: 3 | F21: JOSE LUIS | G21: =[1]DICIEMBRE!$BA$23 -> -0.0032 | S21: =(299*0.16+299)*E21 -> 1040.52 | AJ21: 1040.52 | BA21: =SUM(G21+S21+T21-U21-V21-W21-X21-Y21-Z21-AA21-AB21-AC21-AD21-AE21-AF21-AG21-AH21-AI21-AJ21-AK21-AL21-AM21-AN21-AO21-AP21-AQ21-AR21-AS21-AT21-AU21-AV21-AW21-AX21-AY21-AZ21) -> -0.0032
A22: 5 | B22: AUTOREDES EL BAJIO | D22: COMODATO Mane Troncoso -833 192 6706 Email:admontubored@hotmail.com | E22: 10 | F22: JOSE LUIS | G22: =[1]DICIEMBRE!$BA$24 -> -0.3952 | S22: =(270*0.16+270)*E22 -> 3132 | AA22: 3132 | BA22: =SUM(G22+S22+T22-U22-V22-W22-X22-Y22-Z22-AA22-AB22-AC22-AD22-AE22-AF22-AG22-AH22-AI22-AJ22-AK22-AL22-AM22-AN22-AO22-AP22-AQ22-AR22-AS22-AT22-AU22-AV22-AW22-AX22-AY22-AZ22) -> -0.3952
A23: 6 | B23: BAWOMA CONTROL TOTAL S.A. DE C.V. - FUMIGAZ | C23: Nombre de la Empresa: BAWOMA CONTROL TOTAL S.A. DE C.V. RFC.: BCT100310834 CFDI: Gastos en General Forma de Pago: Transferencia Teléfono: 81 1811 0645 Contacto: Manuel Rico Email: supervisorfumigaz@outlook.com | D23: COMODATO Manuel Rico - 81 1811 0645 Email:supervisorfumigaz@outlook.com | E23: 2 | F23: JOSE LUIS | G23: =[1]DICIEMBRE!$BA$48 -> 696 | S23: =(300*0.16+300)*1 -> 348 | AR23: 348 | BA23: =SUM(G23+S23+T23-U23-V23-W23-X23-Y23-Z23-AA23-AB23-AC23-AD23-AE23-AF23-AG23-AH23-AI23-AJ23-AK23-AL23-AM23-AN23-AO23-AP23-AQ23-AR23-AS23-AT23-AU23-AV23-AW23-AX23-AY23-AZ23) -> 696 | BB23: PDTE. 1 DES-INST. YA PAGADA
A24: 7 | B24: BE ONE SYSTEMS | D24: Lydia Colunga - 81 1176 3598 Edgar Valentin (Pagos) - 81 1970 7000 Email:edgar.valentin@beone.mx lydia@beone.mx | E24: 1 | F24: JOSE LUIS | G24: =[1]DICIEMBRE!$BA$25 -> 0 | S24: =250*0.16+250 -> 290 | AA24: 290 | BA24: =SUM(G24+S24+T24-U24-V24-W24-X24-Y24-Z24-AA24-AB24-AC24-AD24-AE24-AF24-AG24-AH24-AI24-AJ24-AK24-AL24-AM24-AN24-AO24-AP24-AQ24-AR24-AS24-AT24-AU24-AV24-AW24-AX24-AY24-AZ24) -> 0
A25: 8 | B25: BRANDO IVAN MARTINEZ GOVEA - JOSUE FERNANDEZ | D25: Josue Fernandez - 81 1977 0958 Email:jfhz@icloud.com | E25: 5 | F25: JOSE LUIS | G25: =[1]DICIEMBRE!$BA$64 -> 0.0068 | S25: =(250*0.16+250)*E25 -> 1450 | AA25: 1450 | BA25: =SUM(G25+S25+T25-U25-V25-W25-X25-Y25-Z25-AA25-AB25-AC25-AD25-AE25-AF25-AG25-AH25-AI25-AJ25-AK25-AL25-AM25-AN25-AO25-AP25-AQ25-AR25-AS25-AT25-AU25-AV25-AW25-AX25-AY25-AZ25) -> 0.0068
A26: 9 | B26: CARNES RIBHAUS | D26: COMODATO Tania Reyes - 81 1631 2529 Roberta Treviño - 81 1909 7008 Email:facturas@carnesribhaus.com.mx robertaribhaus@gmail.com | E26: 5 | F26: JOSE LUIS | G26: =[1]DICIEMBRE!$BA$27 -> 0.004 | S26: =(279*0.16+279)*E26 -> 1618.2 | AA26: 1618.2 | BA26: =SUM(G26+S26+T26-U26-V26-W26-X26-Y26-Z26-AA26-AB26-AC26-AD26-AE26-AF26-AG26-AH26-AI26-AJ26-AK26-AL26-AM26-AN26-AO26-AP26-AQ26-AR26-AS26-AT26-AU26-AV26-AW26-AX26-AY26-AZ26) -> 0.004
A27: 10 | B27: CARPACK, S.A. DE C.V. | C27: Nombre de la Empresa: CARPACK S.A. DE C.V. RFC.: CAR070302UU2 CFDI: Gastos en General Forma de Pago: TransferenciaTeléfono: 811 277 9070 Contacto: Kelly Mayorga Email: compras@carpack.com.mx; antonioespinosa@carpack.com.mx; elizabeth@carpack.com.mx; | D27: COMODATO Kelly Mayorga - 8112779070 Elizabeth Campos - 8116635976 8181919205 Ext. 107 Email:antonioespinosa@carpack.com.mx; elizabeth@carpack.com.mx; compras@carpack.com.mx; pagos@carpack.com.mx | E27: 5 | F27: JOSE LUIS | G27: =[1]DICIEMBRE!$BA$28 -> 0.0028 | S27: =(280*0.16+280)*E27 -> 1624 | T27: =500*0.16+500 -> 580 | U27: 324.8 | AJ27: 1879.2 | BA27: =SUM(G27+S27+T27-U27-V27-W27-X27-Y27-Z27-AA27-AB27-AC27-AD27-AE27-AF27-AG27-AH27-AI27-AJ27-AK27-AL27-AM27-AN27-AO27-AP27-AQ27-AR27-AS27-AT27-AU27-AV27-AW27-AX27-AY27-AZ27) -> 0.0028 | BB27: COB. ENE'25: 1 DES-INST. Y REBAJE DE 1 MENS. POR BAJA Y PAGADA EN DIC'24
A28: 11 | B28: COMERCIALIZADORA AGROPECUARIA ICK -JORGE ADRIAN RIVERA | C28: Nombre de la Empresa: COMERCIALIZADORA AGROPECUARIA ICK S.A. DE C.V. RFC.: CAI220330VD7 CFDI: Gastos en general Teléfono: 81 2860 1814 Contacto: Adrian Rivera Email: adrian.rmoxica75@gmail.com | D28: COMODATO Adrian Rivera - 81 2860 1814 Email:adrian.rmoxica75@gmail.com | E28: 4 | F28: JOSE LUIS | G28: =[1]DICIEMBRE!$BA$20 -> 0 | S28: =(300*0.16+300)*E28 -> 1392 | AB28: 1392 | BA28: =SUM(G28+S28+T28-U28-V28-W28-X28-Y28-Z28-AA28-AB28-AC28-AD28-AE28-AF28-AG28-AH28-AI28-AJ28-AK28-AL28-AM28-AN28-AO28-AP28-AQ28-AR28-AS28-AT28-AU28-AV28-AW28-AX28-AY28-AZ28) -> 0
A29: 12 | B29: COMERCIALIZADORA FUERZA CEMENTERA | D29: Candy - 81 2634 9644 candymoreno@forzadelnorte.com | E29: 5 | F29: JOSE LUIS | G29: =[1]DICIEMBRE!$BA$31 -> -3480 | S29: =(300*0.16+300)*E29 -> 1740 | BA29: =SUM(G29+S29+T29-U29-V29-W29-X29-Y29-Z29-AA29-AB29-AC29-AD29-AE29-AF29-AG29-AH29-AI29-AJ29-AK29-AL29-AM29-AN29-AO29-AP29-AQ29-AR29-AS29-AT29-AU29-AV29-AW29-AX29-AY29-AZ29) -> -1740 | BB29: PAGO 3 MESES COBRAR HASTA MARZO 2025
A30: 13 | B30: COMERCIALIZADORA Y LOGISTICA SIFAL - ARTURO SIFUENTES | D30: Arturo Sifuentes - 811 521 3582 Silvia Neri Salazar - 811 044 7961 Email: silvia-neri@hotmail.com; ventas@acertrans.com.mx; logisticasifal@hotmail.com; | E30: 5 | F30: JOSE LUIS | G30: =[1]DICIEMBRE!$BA$18 -> -128 | S30: =(350*0.16+350)*E30 -> 2030 | AS30: 2030 | BA30: =SUM(G30+S30+T30-U30-V30-W30-X30-Y30-Z30-AA30-AB30-AC30-AD30-AE30-AF30-AG30-AH30-AI30-AJ30-AK30-AL30-AM30-AN30-AO30-AP30-AQ30-AR30-AS30-AT30-AU30-AV30-AW30-AX30-AY30-AZ30) -> -128
A31: 14 | B31: COMPAÑÍA MADERERA CUAUHTEMOC | D31: COMODATO Daniel Cardenas - 81 2634 0402 Email:recepcionfacturas@ciamaderera.com | E31: 5 | F31: JOSE LUIS | G31: =[1]DICIEMBRE!$BA$77 -> 0.0012 | S31: =(250*0.16+250)*4+(300*0.16+300)*1 -> 1508 | AA31: 1508 | BA31: =SUM(G31+S31+T31-U31-V31-W31-X31-Y31-Z31-AA31-AB31-AC31-AD31-AE31-AF31-AG31-AH31-AI31-AJ31-AK31-AL31-AM31-AN31-AO31-AP31-AQ31-AR31-AS31-AT31-AU31-AV31-AW31-AX31-AY31-AZ31) -> 0.0012
A32: 15 | B32: CONTINENTAL PARABELLUM - GRUPO SAR | D32: Alan Rodriguez finanzas.gposar@gmail.com | E32: 6 | F32: MARIO ULISES | G32: =[1]DICIEMBRE!$BA$32 -> 0 | S32: =(279*0.16+279)*E32 -> 1941.84 | T32: =1658.1*0.16+1658.1 -> 1923.396 | AB32: 3865.24 | BA32: =SUM(G32+S32+T32-U32-V32-W32-X32-Y32-Z32-AA32-AB32-AC32-AD32-AE32-AF32-AG32-AH32-AI32-AJ32-AK32-AL32-AM32-AN32-AO32-AP32-AQ32-AR32-AS32-AT32-AU32-AV32-AW32-AX32-AY32-AZ32) -> -0.004 | BB32: COB. ENE'25: 1 EQP. E INST. NUEVA Y 1 MENS. PROP. 17 DIAS
A33: 16 | B33: DAXS INDUSTRIAL - JOSE HUMBERTO VILLA | D33: Humberto Villa - 81 1487 4381 Email:daxsind@hotmail.com | E33: 2 | G33: =[1]DICIEMBRE!$BA$61 -> 2598.4 | BA33: =SUM(G33+S33+T33-U33-V33-W33-X33-Y33-Z33-AA33-AB33-AC33-AD33-AE33-AF33-AG33-AH33-AI33-AJ33-AK33-AL33-AM33-AN33-AO33-AP33-AQ33-AR33-AS33-AT33-AU33-AV33-AW33-AX33-AY33-AZ33) -> 2598.4 | BB33: BAJA
A34: 17 | B34: DISTRIBUIDORA FERRELECTRICA Y MATERIALES EXPRESS - DEX MATERIALES | D34: Aleyda - 81 3402 1812 Rolando Ziragem 811 077 1470 812 597 2700 / 812 332 3606 oficina@dexmateriales.com; rzgc@hotmail.com; rolando@dexmateriales.com; | E34: 9 | F34: JOSE LUIS | G34: =[1]DICIEMBRE!$BA$34 -> 0 | S34: 0 | BA34: =SUM(G34+S34+T34-U34-V34-W34-X34-Y34-Z34-AA34-AB34-AC34-AD34-AE34-AF34-AG34-AH34-AI34-AJ34-AK34-AL34-AM34-AN34-AO34-AP34-AQ34-AR34-AS34-AT34-AU34-AV34-AW34-AX34-AY34-AZ34) -> 0 | BB34: PAGARA 6 MENS. COBRAR HASTA EL MES DE MARZO 2025 CAMBIA A ESQUEMA DE MENSUALIDAD 06-SEPTIEMBRE-2024 Y DA DE BAJA 3 UNIDADES Y SE SEPARA CUENTA A COMERCIALIZADORA FUERZA CEMENTERA
A35: 18 | B35: EDGAR ALBERTO CORTEZ TREVIÑO | D35: Edgar Cortez - 81 8185 6454 | E35: 1 | F35: JOSE LUIS | G35: =[1]DICIEMBRE!$BA$35 -> 0 | S35: =(250*0.16+250)*E35 -> 290 | AE35: 290 | BA35: =SUM(G35+S35+T35-U35-V35-W35-X35-Y35-Z35-AA35-AB35-AC35-AD35-AE35-AF35-AG35-AH35-AI35-AJ35-AK35-AL35-AM35-AN35-AO35-AP35-AQ35-AR35-AS35-AT35-AU35-AV35-AW35-AX35-AY35-AZ35) -> 0
A36: 19 | B36: ELIZABETH RENTERIA REVILLA | C36: Nombre de la Empresa: ELIZABETH RENTERÍA REVILLA RFC. RERE760807SX9 CFDI: Gastos en general Forma de Pago: TransferenciaTeléfono: 811 810 0155 Contacto: Elizabeth Rentería Email: e.lic@live.com.mx | D36: Elizabeth Renteria - 811 810 0155 Email:e.lic@live.com.mx | E36: 2 | F36: JOSE LUIS | G36: =[1]DICIEMBRE!$BA$37 -> 0 | S36: =(250*0.16+250)*E36 -> 580 | T36: =1850*0.16+1850 -> 2146 | AE36: =290+2436 -> 2726 | BA36: =SUM(G36+S36+T36-U36-V36-W36-X36-Y36-Z36-AA36-AB36-AC36-AD36-AE36-AF36-AG36-AH36-AI36-AJ36-AK36-AL36-AM36-AN36-AO36-AP36-AQ36-AR36-AS36-AT36-AU36-AV36-AW36-AX36-AY36-AZ36) -> 0 | BB36: COB. ENE'25: 1 EQP. E INST. NUEVA COBRAR EN FEB 1 MENS. PROP. 20 DIAS
A37: 20 | B37: ENDER INDUSTRIAL (EMMANUEL VAZQUEZ - SINERGIX ) | C37: Nombre de la Empresa: ENDER INDUSTRIAL S.A. DE C.V. RFC.: SIS1703089V6 CFDI: Gastos en General. Forma de Pago: Transferencia Teléfono: 813 055 7409 / 81) 2141 0506 Contacto: Emmanuel Vázquez / Sonia Lugo Email: emmanuel@sinergix.net; sonia@sinergix.net; | D37: COMODATO Emmanuel Vazquez - 81 3055 7409 Sonia Lugo (pagos) - 81 2141 0506 Email:sandra@enderindustrial.com claudia@enderindustrial.com belen@enderindustrial.com facturas@enderindustrial.com; emmanuel@sinergix.net; | E37: 7 | F37: JOSE LUIS | G37: =[1]DICIEMBRE!$BA$38 -> -753.9924 | S37: =(350*0.16+350)*E37 -> 2842 | AE37: 2842 | BA37: =SUM(G37+S37+T37-U37-V37-W37-X37-Y37-Z37-AA37-AB37-AC37-AD37-AE37-AF37-AG37-AH37-AI37-AJ37-AK37-AL37-AM37-AN37-AO37-AP37-AQ37-AR37-AS37-AT37-AU37-AV37-AW37-AX37-AY37-AZ37) -> -753.9924
A38: 21 | B38: ENDO LASER MICROQUIRURGICO - INSTITUTO VIDAURRI DE OJOS (DANIELA MEDELLIN) | D38: Daniela Medellín - 81 1588 8485 Email:monitoreo@endolaser.com.mx | E38: 4 | F38: JOSE LUIS | G38: =[1]DICIEMBRE!$BA$59 -> 6.8212103e-13 | S38: =(249*0.16+249)*E38 -> 1155.36 | AE38: 1155.36 | BA38: =SUM(G38+S38+T38-U38-V38-W38-X38-Y38-Z38-AA38-AB38-AC38-AD38-AE38-AF38-AG38-AH38-AI38-AJ38-AK38-AL38-AM38-AN38-AO38-AP38-AQ38-AR38-AS38-AT38-AU38-AV38-AW38-AX38-AY38-AZ38) -> 9.094947e-13
A39: 22 | B39: EXTINTORES Y EQUIPOS MONTERREY (SERGIO GONZALEZ) | D39: COMODATO Sergio Gonzalez - 81 8654 2753 sergio.jr987@outlook.com | E39: 2 | F39: JOSE LUIS | G39: =[1]DICIEMBRE!$BA$41 -> 0 | S39: =(300*0.16+300)*2 -> 696 | AH39: 696 | BA39: =SUM(G39+S39+T39-U39-V39-W39-X39-Y39-Z39-AA39-AB39-AC39-AD39-AE39-AF39-AG39-AH39-AI39-AJ39-AK39-AL39-AM39-AN39-AO39-AP39-AQ39-AR39-AS39-AT39-AU39-AV39-AW39-AX39-AY39-AZ39) -> 0 | BB39: PDTE 1 INSTALACION YA PAGADA SOLO COBRAR PROP. CUANDO SE INSTALE
A40: 23 | B40: FERNANDO RAFAEL GONZALEZ MONTEMAYOR (SERVICIO DE PLATAFORMA) | C40: Nombre de la Empresa: GOMO SERVICES Contacto: FERNANDO DISATEL Email: frgm_76@hotmail.com Remisiones con IVA | D40: Fernando Disatel - 81 1799 2490 Email:frgm_76@hotmail.com | E40: 674 | F40: JOSE LUIS | G40: =[1]DICIEMBRE!$BA$42 -> 3220.026 | S40: =(38.8*0.16+38.8)*E40 -> 30335.392 | T40: =38.8*0.16+38.8 -> 45.008 | AO40: 30380.4 | BA40: =SUM(G40+S40+T40-U40-V40-W40-X40-Y40-Z40-AA40-AB40-AC40-AD40-AE40-AF40-AG40-AH40-AI40-AJ40-AK40-AL40-AM40-AN40-AO40-AP40-AQ40-AR40-AS40-AT40-AU40-AV40-AW40-AX40-AY40-AZ40) -> 3220.026 | BB40: COB. ENE'25: INGRESO DE 1 UNIDAD
A41: 24 | B41: FERNANDO REYES HERNANDES | D41: COMODATO Fernando Reyes - 81 1821 3781 Viridiana Flores - 81 1796 4130 arnol84reyeshdz@gmail.com | E41: 1 | F41: JOSE LUIS | G41: =[1]DICIEMBRE!$BA$43 -> 348 | S41: =(300*0.16+300)*E41 -> 348 | AB41: 696 | BA41: =SUM(G41+S41+T41-U41-V41-W41-X41-Y41-Z41-AA41-AB41-AC41-AD41-AE41-AF41-AG41-AH41-AI41-AJ41-AK41-AL41-AM41-AN41-AO41-AP41-AQ41-AR41-AS41-AT41-AU41-AV41-AW41-AX41-AY41-AZ41) -> 0
A42: 25 | B42: FINPAIS | C42: Nombre de la Empresa: FINPAIS S.A. DE C.V. RFC. FCO130429629 CFDI: Gastos en general Forma de Pago: TransferenciaTeléfono: 81 8208 7559 Contacto: Katty Email: administracion@finpais.com.mx | D42: COMODATO Katty - 81 8208 7559 Email:administracion@finpais.com.mx | E42: 7 | F42: JOSE LUIS | G42: =[1]DICIEMBRE!$BA$44 -> 2598.3956 | S42: =(320*0.16+320)*E42 -> 2598.4 | T42: =250*0.16+250 -> 290 | BA42: =SUM(G42+S42+T42-U42-V42-W42-X42-Y42-Z42-AA42-AB42-AC42-AD42-AE42-AF42-AG42-AH42-AI42-AJ42-AK42-AL42-AM42-AN42-AO42-AP42-AQ42-AR42-AS42-AT42-AU42-AV42-AW42-AX42-AY42-AZ42) -> 5486.7956 | BB42: COB. ENE'25: 1 VISITA EN FALSO Y 1 FACTURA PDTE.
...

Sheet FEBRERO
B2: Cobranza Total 2025 | D2: =SUM(S2+S3+S4+S5+S6+S7+S8+S9+S10+S11+S12+S13+D5) -> 675018.29 | E2: Saldos 2024 | S2: =G213 -> 46667.546
E3: Enero`25 | S3: =H213-S2 -> 7113.248
B4: COBRANZA FEBRERO 2025 | E4: Febrero´25 | S4: =I213 -> 0
B5: Febrero'2025 | D5: =S213+T213+U213 -> 621237.49 | E5: Marzo'25 | S5: =J213 -> 0
B6: Recuperación del 01 al 02 | D6: =SUM(V213:W213) -> 15004.8 | E6: Abril´25 | S6: =K213 -> 0
B7: Recuperación del 03 al 09 | D7: =SUM(X213:AD213) -> 159634.97 | E7: Mayo´25 | S7: =L213 -> 0
B8: Recuperación del 10 al 16 | D8: =SUM(AE213:AK213) -> 168928.58 | E8: Junio´25 | S8: =M213 -> 0
B9: Recuperación del 17 al 23 | D9: =SUM(AL213:AR213) -> 193494.59 | E9: Julio´25 | S9: =N213 -> 0
B10: Recuperación del 24 al 28 | D10: =SUM(AS213:AW213) -> 76341.7 | E10: Agosto'25 | S10: =O213 -> 0
E11: Septiembre'25 | S11: =P213 -> 0
E12: Octubre'25 | S12: =Q213 -> 0
B13: Total Recuperado | D13: =SUM(D6:D11) -> 613404.64 | E13: Noviembre'25 | S13: =R213 -> 0
B14: Por Recuperar | D14: =D2-D13 -> 61613.647 | E14: Total de Arrastre: | S14: =SUM(S2:S13) -> 53780.794
A16: NO. | B16: CLIENTE | C16: DATOS FISCALES | D16: CONTACTO | E16: UNI | F16: VENTA | G16: ATRASO | S16: IMPORTE FEB´2025 | T16: SERV. EXTRAS | U16: DES % | V16: 1 | W16: 2 | X16: 3 | Y16: 4 | Z16: 5 | AA16: 6 | AB16: 7 | AC16: 8 | AD16: 9 | AE16: 10 | AF16: 11 | AG16: 12 | AH16: 13 | AI16: 14 | AJ16: 15 | AK16: 16 | AL16: 17 | AM16: 18 | AN16: 19 | AO16: 20 | AP16: 21 | AQ16: 22 | AR16: 23 | AS16: 24 | AT16: 25 | AU16: 26 | AV16: 27 | AW16: 28 | AX16: SALDOS PENDIENTES | AY16: COMENTARIOS | AZ16: ESTATUS PROMESA DE PAGO
G17: 2024 | H17: ENE | I17: FEB | J17: MAR | K17: ABR | L17: MAY | M17: JUN | N17: JUL | O17: AGO | P17: SEP | Q17: OCT | R17: NOV | V17: S | W17: D | X17: L | Y17: M | Z17: M | AA17: J | AB17: V | AC17: S | AD17: D | AE17: L | AF17: M | AG17: M | AH17: J | AI17: V | AJ17: S | AK17: D | AL17: L | AM17: M | AN17: M | AO17: J | AP17: V | AQ17: S | AR17: D | AS17: L | AT17: M | AU17: M | AV17: J | AW17: V
A18: 1 | B18: ADRIANA ORANDAY DAVILA - RODRIGO ALANIS | D18: Rodrigo Alanis - 81 2861 1509 Email:adrianaoranday@gmail.com alanis_rodrigo@hotmail.com | E18: 1 | F18: JOSE LUIS | G18: =[1]DICIEMBRE!$BA$91 -> 290 | H18: =ENERO!BA18 -> 580 | S18: =(250*0.16+250)*E18 -> 290 | AX18: =SUM(H18+S18+T18-U18-V18-W18-X18-Y18-Z18-AA18-AB18-AC18-AD18-AE18-AF18-AG18-AH18-AI18-AJ18-AK18-AL18-AM18-AN18-AO18-AP18-AQ18-AR18-AS18-AT18-AU18-AV18-AW18) -> 870
A19: 2 | B19: ALIMENTOS REGIOMONTANOS PERCAM - ALIMENTOS GRUPER | C19: Nombre de la Empresa: ALIMENTOS GUPER S.A. DE C.V. Contacto: Nancy Paola Perales Teléfono: 811 801 4266 Email: alimentosgupersacv@gmail.com | D19: Alejandro Garcia - 81 2034 3938 Nancy Paola Perales - 8118014266 Alimentosregiopercam@gmail.com alimentosgupersacv@gmail.com | E19: 18 | F19: DANIEL ESTRADA | G19: =[1]DICIEMBRE!$BA$21 -> -0.3952 | H19: =ENERO!BA19 -> -0.3952 | S19: =(300*0.16+300)*E19 -> 6264 | AB19: 6263.6 | AX19: =SUM(H19+S19+T19-U19-V19-W19-X19-Y19-Z19-AA19-AB19-AC19-AD19-AE19-AF19-AG19-AH19-AI19-AJ19-AK19-AL19-AM19-AN19-AO19-AP19-AQ19-AR19-AS19-AT19-AU19-AV19-AW19) -> 0.0048
A20: 3 | B20: AUTO EXPRESS GERAL 21 S.A. DE C.V. - LUIS GERARDO BOLAÑOS GARCIA | C20: Nombre de la Empresa: LUIS GERARDO BOLAÑOS GARCIA RFC. BOGL8702094H5 CFDI: Gastos en general Forma de Pago: Transferencia Teléfono: 811 027 0226 Contacto: Luis Gerardo Bolaños García Email: luismty0902@gmail.com; | D20: Luis Gerardo Bolaños García - 811 027 0226 Email:expressgeral19@gmail.com luismty0902@gmail.com | E20: 5 | F20: JOSE LUIS | G20: =[1]DICIEMBRE!$BA$75 -> 3190.0028 | H20: =ENERO!BA20 -> 0.0028 | S20: =(280*0.16+280)*E20 -> 1624 | Z20: 1624 | AX20: =SUM(H20+S20+T20-U20-V20-W20-X20-Y20-Z20-AA20-AB20-AC20-AD20-AE20-AF20-AG20-AH20-AI20-AJ20-AK20-AL20-AM20-AN20-AO20-AP20-AQ20-AR20-AS20-AT20-AU20-AV20-AW20) -> 0.0028
A21: 4 | B21: AUTOEXPRESS MATA | C21: Nombre de la Empresa: AUTOEXPRESS MATA S.A. DE C.V. RFC. AMA040520BZ2 CFDI : Forma de Pago: Transferencia Teléfono: 81 1029 1017 Contacto: Edgar Garza Email: | D21: COMODATO Edgar Garza - 81 1029 1017 | E21: 3 | F21: JOSE LUIS | G21: =[1]DICIEMBRE!$BA$23 -> -0.0032 | H21: =ENERO!BA21 -> -0.0032 | S21: =(299*0.16+299)*E21 -> 1040.52 | AM21: 1040.52 | AX21: =SUM(H21+S21+T21-U21-V21-W21-X21-Y21-Z21-AA21-AB21-AC21-AD21-AE21-AF21-AG21-AH21-AI21-AJ21-AK21-AL21-AM21-AN21-AO21-AP21-AQ21-AR21-AS21-AT21-AU21-AV21-AW21) -> -0.0032
A22: 5 | B22: AUTOREDES EL BAJIO | D22: COMODATO Mane Troncoso -833 192 6706 Email:admontubored@hotmail.com | E22: 10 | F22: JOSE LUIS | G22: =[1]DICIEMBRE!$BA$24 -> -0.3952 | H22: =ENERO!BA22 -> -0.3952 | S22: =(270*0.16+270)*E22 -> 3132 | AB22: 3131.6 | AX22: =SUM(H22+S22+T22-U22-V22-W22-X22-Y22-Z22-AA22-AB22-AC22-AD22-AE22-AF22-AG22-AH22-AI22-AJ22-AK22-AL22-AM22-AN22-AO22-AP22-AQ22-AR22-AS22-AT22-AU22-AV22-AW22) -> 0.0048
A23: 6 | B23: BAWOMA CONTROL TOTAL S.A. DE C.V. - FUMIGAZ | C23: Nombre de la Empresa: BAWOMA CONTROL TOTAL S.A. DE C.V. RFC.: BCT100310834 CFDI: Gastos en General Forma de Pago: Transferencia Teléfono: 81 1811 0645 Contacto: Manuel Rico Email: supervisorfumigaz@outlook.com | D23: COMODATO Manuel Rico - 81 1811 0645 Email:supervisorfumigaz@outlook.com | E23: 2 | F23: JOSE LUIS | G23: =[1]DICIEMBRE!$BA$48 -> 696 | H23: =ENERO!BA23 -> 696 | S23: =(300*0.16+300)*1 -> 348 | AU23: 1044 | AX23: =SUM(H23+S23+T23-U23-V23-W23-X23-Y23-Z23-AA23-AB23-AC23-AD23-AE23-AF23-AG23-AH23-AI23-AJ23-AK23-AL23-AM23-AN23-AO23-AP23-AQ23-AR23-AS23-AT23-AU23-AV23-AW23) -> 0 | AY23: PDTE. 1 DES-INST. YA PAGADA
A24: 7 | B24: BE ONE SYSTEMS | D24: Lydia Colunga - 81 1176 3598 Edgar Valentin (Pagos) - 81 1970 7000 Email:edgar.valentin@beone.mx lydia@beone.mx | E24: 1 | F24: JOSE LUIS | G24: =[1]DICIEMBRE!$BA$25 -> 0 | H24: =ENERO!BA24 -> 0 | S24: =250*0.16+250 -> 290 | Y24: 290 | AX24: =SUM(H24+S24+T24-U24-V24-W24-X24-Y24-Z24-AA24-AB24-AC24-AD24-AE24-AF24-AG24-AH24-AI24-AJ24-AK24-AL24-AM24-AN24-AO24-AP24-AQ24-AR24-AS24-AT24-AU24-AV24-AW24) -> 0
A25: 8 | B25: BRANDO IVAN MARTINEZ GOVEA - JOSUE FERNANDEZ | D25: Josue Fernandez - 81 1977 0958 Email:jfhz@icloud.com | E25: 5 | F25: JOSE LUIS | G25: =[1]DICIEMBRE!$BA$64 -> 0.0068 | H25: =ENERO!BA25 -> 0.0068 | S25: =(250*0.16+250)*E25 -> 1450 | AB25: 1450.01 | AX25: =SUM(H25+S25+T25-U25-V25-W25-X25-Y25-Z25-AA25-AB25-AC25-AD25-AE25-AF25-AG25-AH25-AI25-AJ25-AK25-AL25-AM25-AN25-AO25-AP25-AQ25-AR25-AS25-AT25-AU25-AV25-AW25) -> -0.0032
A26: 9 | B26: CARLOS JONATHAN MARTINEZ RIVERA | D26: Jonathan Rivera - 81 1696 5321 jonathanrivera22929@gmail.com | E26: 1 | F26: JOSE LUIS | G26: =[1]DICIEMBRE!$BA$134 -> 0 | H26: =ENERO!BA139 -> 48 | S26: =(300*0.16+300)*E26 -> 348 | Z26: 396 | AX26: =SUM(H26+S26+T26-U26-V26-W26-X26-Y26-Z26-AA26-AB26-AC26-AD26-AE26-AF26-AG26-AH26-AI26-AJ26-AK26-AL26-AM26-AN26-AO26-AP26-AQ26-AR26-AS26-AT26-AU26-AV26-AW26) -> 0 | AY26: CAMBIA A ESQUEMA DE FACTURACION 05-FEBRERO-2025
A27: 10 | B27: CARNES RIBHAUS | D27: COMODATO Tania Reyes - 81 1631 2529 Roberta Treviño - 81 1909 7008 Email:facturas@carnesribhaus.com.mx robertaribhaus@gmail.com | E27: 5 | F27: JOSE LUIS | G27: =[1]DICIEMBRE!$BA$27 -> 0.004 | H27: =ENERO!BA26 -> 0.004 | S27: =(279*0.16+279)*E27 -> 1618.2 | Z27: 1618.2 | AX27: =SUM(H27+S27+T27-U27-V27-W27-X27-Y27-Z27-AA27-AB27-AC27-AD27-AE27-AF27-AG27-AH27-AI27-AJ27-AK27-AL27-AM27-AN27-AO27-AP27-AQ27-AR27-AS27-AT27-AU27-AV27-AW27) -> 0.004
A28: 11 | B28: CARPACK, S.A. DE C.V. | C28: Nombre de la Empresa: CARPACK S.A. DE C.V. RFC.: CAR070302UU2 CFDI: Gastos en General Forma de Pago: TransferenciaTeléfono: 811 277 9070 Contacto: Kelly Mayorga Email: compras@carpack.com.mx; antonioespinosa@carpack.com.mx; elizabeth@carpack.com.mx; | D28: COMODATO Kelly Mayorga - 8112779070 Elizabeth Campos - 8116635976 8181919205 Ext. 107 Email:antonioespinosa@carpack.com.mx; elizabeth@carpack.com.mx; compras@carpack.com.mx; pagos@carpack.com.mx | E28: 5 | F28: JOSE LUIS | G28: =[1]DICIEMBRE!$BA$28 -> 0.0028 | H28: =ENERO!BA27 -> 0.0028 | S28: =(280*0.16+280)*E28 -> 1624 | Z28: 1624 | AX28: =SUM(H28+S28+T28-U28-V28-W28-X28-Y28-Z28-AA28-AB28-AC28-AD28-AE28-AF28-AG28-AH28-AI28-AJ28-AK28-AL28-AM28-AN28-AO28-AP28-AQ28-AR28-AS28-AT28-AU28-AV28-AW28) -> 0.0028
A29: 12 | B29: COMERCIALIZADORA AGROPECUARIA ICK -JORGE ADRIAN RIVERA | C29: Nombre de la Empresa: COMERCIALIZADORA AGROPECUARIA ICK S.A. DE C.V. RFC.: CAI220330VD7 CFDI: Gastos en general Teléfono: 81 2860 1814 Contacto: Adrian Rivera Email: adrian.rmoxica75@gmail.com | D29: COMODATO Adrian Rivera - 81 2860 1814 Email:adrian.rmoxica75@gmail.com | E29: 4 | F29: JOSE LUIS | G29: =[1]DICIEMBRE!$BA$20 -> 0 | H29: =ENERO!BA28 -> 0 | S29: =(300*0.16+300)*E29 -> 1392 | AB29: 1392 | AX29: =SUM(H29+S29+T29-U29-V29-W29-X29-Y29-Z29-AA29-AB29-AC29-AD29-AE29-AF29-AG29-AH29-AI29-AJ29-AK29-AL29-AM29-AN29-AO29-AP29-AQ29-AR29-AS29-AT29-AU29-AV29-AW29) -> 0
A30: 13 | B30: COMERCIALIZADORA FUERZA CEMENTERA | D30: Candy - 81 2634 9644 candymoreno@forzadelnorte.com | E30: 5 | F30: JOSE LUIS | G30: =[1]DICIEMBRE!$BA$31 -> -3480 | H30: =ENERO!BA29 -> -1740 | S30: =(300*0.16+300)*E30 -> 1740 | AX30: =SUM(H30+S30+T30-U30-V30-W30-X30-Y30-Z30-AA30-AB30-AC30-AD30-AE30-AF30-AG30-AH30-AI30-AJ30-AK30-AL30-AM30-AN30-AO30-AP30-AQ30-AR30-AS30-AT30-AU30-AV30-AW30) -> 0 | AY30: PAGO 3 MESES COBRAR HASTA MARZO 2025
A31: 14 | B31: COMERCIALIZADORA Y LOGISTICA SIFAL - ARTURO SIFUENTES | D31: Arturo Sifuentes - 811 521 3582 Email: silvia-neri@hotmail.com; ventas@acertrans.com.mx; logisticasifal@hotmail.com; | E31: 5 | F31: JOSE LUIS | G31: =[1]DICIEMBRE!$BA$18 -> -128 | H31: =ENERO!BA30 -> -128 | S31: =(350*0.16+350)*E31 -> 2030 | AO31: 2030 | AX31: =SUM(H31+S31+T31-U31-V31-W31-X31-Y31-Z31-AA31-AB31-AC31-AD31-AE31-AF31-AG31-AH31-AI31-AJ31-AK31-AL31-AM31-AN31-AO31-AP31-AQ31-AR31-AS31-AT31-AU31-AV31-AW31) -> -128
A32: 15 | B32: COMPAÑÍA MADERERA CUAUHTEMOC | D32: COMODATO Daniel Cardenas - 81 2634 0402 Email:recepcionfacturas@ciamaderera.com | E32: 5 | F32: JOSE LUIS | G32: =[1]DICIEMBRE!$BA$77 -> 0.0012 | H32: =ENERO!BA31 -> 0.0012 | S32: =(250*0.16+250)*4+(300*0.16+300)*1 -> 1508 | Y32: 1508 | AX32: =SUM(H32+S32+T32-U32-V32-W32-X32-Y32-Z32-AA32-AB32-AC32-AD32-AE32-AF32-AG32-AH32-AI32-AJ32-AK32-AL32-AM32-AN32-AO32-AP32-AQ32-AR32-AS32-AT32-AU32-AV32-AW32) -> 0.0012
A33: 16 | B33: CONTINENTAL PARABELLUM - GRUPO SAR | D33: Alan Rodriguez finanzas.gposar@gmail.com | E33: 6 | F33: MARIO ULISES | G33: =[1]DICIEMBRE!$BA$32 -> 0 | H33: =ENERO!BA32 -> -0.004 | S33: =(279*0.16+279)*E33 -> 1941.84 | AB33: 1941.84 | AX33: =SUM(H33+S33+T33-U33-V33-W33-X33-Y33-Z33-AA33-AB33-AC33-AD33-AE33-AF33-AG33-AH33-AI33-AJ33-AK33-AL33-AM33-AN33-AO33-AP33-AQ33-AR33-AS33-AT33-AU33-AV33-AW33) -> -0.004
A34: 17 | B34: DAXS INDUSTRIAL - JOSE HUMBERTO VILLA | D34: Humberto Villa - 81 1487 4381 Email:daxsind@hotmail.com | E34: 2 | G34: =[1]DICIEMBRE!$BA$61 -> 2598.4 | H34: =ENERO!BA33 -> 2598.4 | AX34: =SUM(H34+S34+T34-U34-V34-W34-X34-Y34-Z34-AA34-AB34-AC34-AD34-AE34-AF34-AG34-AH34-AI34-AJ34-AK34-AL34-AM34-AN34-AO34-AP34-AQ34-AR34-AS34-AT34-AU34-AV34-AW34) -> 2598.4 | AY34: BAJA
A35: 18 | B35: DISTRIBUIDORA FERRELECTRICA Y MATERIALES EXPRESS - DEX MATERIALES | D35: Aleyda - 81 3402 1812 Rolando Ziragem 811 077 1470 812 597 2700 / 812 332 3606 oficina@dexmateriales.com; rzgc@hotmail.com; rolando@dexmateriales.com; | E35: 9 | F35: JOSE LUIS | G35: =[1]DICIEMBRE!$BA$34 -> 0 | H35: =ENERO!BA34 -> 0 | S35: 0 | AX35: =SUM(H35+S35+T35-U35-V35-W35-X35-Y35-Z35-AA35-AB35-AC35-AD35-AE35-AF35-AG35-AH35-AI35-AJ35-AK35-AL35-AM35-AN35-AO35-AP35-AQ35-AR35-AS35-AT35-AU35-AV35-AW35) -> 0 | AY35: PAGARA 6 MENS. COBRAR HASTA EL MES DE MARZO 2025 CAMBIA A ESQUEMA DE MENSUALIDAD 06-SEPTIEMBRE-2024 Y DA DE BAJA 3 UNIDADES Y SE SEPARA CUENTA A COMERCIALIZADORA FUERZA CEMENTERA
A36: 19 | B36: EDGAR ALBERTO CORTEZ TREVIÑO | D36: Edgar Cortez - 81 8185 6454 | E36: 1 | F36: JOSE LUIS | G36: =[1]DICIEMBRE!$BA$35 -> 0 | H36: =ENERO!BA35 -> 0 | S36: =(250*0.16+250)*E36 -> 290 | AC36: 290 | AX36: =SUM(H36+S36+T36-U36-V36-W36-X36-Y36-Z36-AA36-AB36-AC36-AD36-AE36-AF36-AG36-AH36-AI36-AJ36-AK36-AL36-AM36-AN36-AO36-AP36-AQ36-AR36-AS36-AT36-AU36-AV36-AW36) -> 0
A37: 20 | B37: ELIZABETH RENTERIA REVILLA | C37: Nombre de la Empresa: ELIZABETH RENTERÍA REVILLA RFC. RERE760807SX9 CFDI: Gastos en general Forma de Pago: TransferenciaTeléfono: 811 810 0155 Contacto: Elizabeth Rentería Email: e.lic@live.com.mx | D37: Elizabeth Renteria - 811 810 0155 Email:e.lic@live.com.mx | E37: 2 | F37: JOSE LUIS | G37: =[1]DICIEMBRE!$BA$37 -> 0 | H37: =ENERO!BA36 -> 0 | S37: =(250*0.16+250)*1+(166.66*0.16+166.66) -> 483.3256 | AH37: 483.33 | AX37: =SUM(H37+S37+T37-U37-V37-W37-X37-Y37-Z37-AA37-AB37-AC37-AD37-AE37-AF37-AG37-AH37-AI37-AJ37-AK37-AL37-AM37-AN37-AO37-AP37-AQ37-AR37-AS37-AT37-AU37-AV37-AW37) -> -0.0044 | AY37: COB. FEB'25: 1 MENS. PROP. 20 DIAS COBRAR EN MARZO MENS. COMPL.
A38: 21 | B38: ENDER INDUSTRIAL (EMMANUEL VAZQUEZ - SINERGIX ) | C38: Nombre de la Empresa: ENDER INDUSTRIAL S.A. DE C.V. RFC.: SIS1703089V6 CFDI: Gastos en General. Forma de Pago: Transferencia Teléfono: 813 055 7409 / 81) 2141 0506 Contacto: Emmanuel Vázquez / Sonia Lugo Email: emmanuel@sinergix.net; sonia@sinergix.net; | D38: COMODATO Emmanuel Vazquez - 81 3055 7409 Sonia Lugo (pagos) - 81 2141 0506 Email:sandra@enderindustrial.com claudia@enderindustrial.com belen@enderindustrial.com facturas@enderindustrial.com; emmanuel@sinergix.net; | E38: 7 | F38: JOSE LUIS | G38: =[1]DICIEMBRE!$BA$38 -> -753.9924 | H38: =ENERO!BA37 -> -753.9924 | S38: =(350*0.16+350)*E38 -> 2842 | AA38: 2842 | AX38: =SUM(H38+S38+T38-U38-V38-W38-X38-Y38-Z38-AA38-AB38-AC38-AD38-AE38-AF38-AG38-AH38-AI38-AJ38-AK38-AL38-AM38-AN38-AO38-AP38-AQ38-AR38-AS38-AT38-AU38-AV38-AW38) -> -753.9924
A39: 22 | B39: ENDO LASER MICROQUIRURGICO - INSTITUTO VIDAURRI DE OJOS (DANIELA MEDELLIN) | D39: Daniela Medellín - 81 1588 8485 Email:monitoreo@endolaser.com.mx | E39: 4 | F39: JOSE LUIS | G39: =[1]DICIEMBRE!$BA$59 -> 6.8212103e-13 | H39: =ENERO!BA38 -> 9.094947e-13 | S39: =(249*0.16+249)*E39 -> 1155.36 | AI39: 1155.36 | AX39: =SUM(H39+S39+T39-U39-V39-W39-X39-Y39-Z39-AA39-AB39-AC39-AD39-AE39-AF39-AG39-AH39-AI39-AJ39-AK39-AL39-AM39-AN39-AO39-AP39-AQ39-AR39-AS39-AT39-AU39-AV39-AW39) -> 1.1368684e-12
A40: 23 | B40: EXTINTORES Y EQUIPOS MONTERREY (SERGIO GONZALEZ) | D40: COMODATO Gabriela - 81 2077 4512 Sergio Gonzalez - 81 8654 2753 sergio.jr987@outlook.com | E40: 2 | F40: JOSE LUIS | G40: =[1]DICIEMBRE!$BA$41 -> 0 | H40: =ENERO!BA39 -> 0 | S40: =(300*0.16+300)*2 -> 696 | AB40: 696 | AX40: =SUM(H40+S40+T40-U40-V40-W40-X40-Y40-Z40-AA40-AB40-AC40-AD40-AE40-AF40-AG40-AH40-AI40-AJ40-AK40-AL40-AM40-AN40-AO40-AP40-AQ40-AR40-AS40-AT40-AU40-AV40-AW40) -> 0 | AY40: PDTE 1 INSTALACION YA PAGADA SOLO COBRAR PROP. CUANDO SE INSTALE
A41: 24 | B41: FERNANDO RAFAEL GONZALEZ MONTEMAYOR (SERVICIO DE PLATAFORMA) | C41: Nombre de la Empresa: GOMO SERVICES Contacto: FERNANDO DISATEL Email: frgm_76@hotmail.com Remisiones con IVA | D41: Fernando Disatel - 81 1799 2490 Email:frgm_76@hotmail.com | E41: 674 | F41: JOSE LUIS | G41: =[1]DICIEMBRE!$BA$42 -> 3220.026 | H41: =ENERO!BA40 -> 3220.026 | S41: =(38.8*0.16+38.8)*E41 -> 30335.392 | AM41: 30335.39 | AX41: =SUM(H41+S41+T41-U41-V41-W41-X41-Y41-Z41-AA41-AB41-AC41-AD41-AE41-AF41-AG41-AH41-AI41-AJ41-AK41-AL41-AM41-AN41-AO41-AP41-AQ41-AR41-AS41-AT41-AU41-AV41-AW41) -> 3220.028
A42: 25 | B42: FERNANDO REYES HERNANDES | D42: COMODATO Fernando Reyes - 81 1821 3781 Viridiana Flores - 81 1796 4130 arnol84reyeshdz@gmail.com | E42: 1 | F42: JOSE LUIS | G42: =[1]DICIEMBRE!$BA$43 -> 348 | H42: =ENERO!BA41 -> 0 | S42: =(300*0.16+300)*E42 -> 348 | AE42: 348 | AX42: =SUM(H42+S42+T42-U42-V42-W42-X42-Y42-Z42-AA42-AB42-AC42-AD42-AE42-AF42-AG42-AH42-AI42-AJ42-AK42-AL42-AM42-AN42-AO42-AP42-AQ42-AR42-AS42-AT42-AU42-AV42-AW42) -> 0
...

Sheet MARZO
B2: Cobranza Total 2025 | D2: =SUM(S2+S3+S4+S5+S6+S7+S8+S9+S10+S11+S12+S13+D5) -> 626927.51 | E2: Saldos 2024 | S2: =G216 -> 34476.146
E3: Enero`25 | S3: =H216-S2 -> 9667.248
B4: COBRANZA MARZO 2025 | E4: Febrero´25 | S4: =I216 -> 6487.8524
B5: MARZO'2025 | D5: =S216+T216+U216 -> 576296.26 | E5: Marzo'25 | S5: =J216 -> 0
B6: Recuperación del 01 al 02 | D6: =SUM(V216:W216) -> 4330.86 | E6: Abril´25 | S6: =K216 -> 0
B7: Recuperación del 03 al 09 | D7: =SUM(X216:AD216) -> 146485.36 | E7: Mayo´25 | S7: =L216 -> 0
B8: Recuperación del 10 al 16 | D8: =SUM(AE216:AK216) -> 93625.4 | E8: Junio´25 | S8: =M216 -> 0
B9: Recuperación del 17 al 23 | D9: =SUM(AL216:AR216) -> 154914.9 | E9: Julio´25 | S9: =N216 -> 0
B10: Recuperación del 24 al 30 | D10: =SUM(AS216:AY216) -> 163928.32 | E10: Agosto'25 | S10: =O216 -> 0
B11: Recuperación del 31 | D11: =SUM(AZ216) -> 18015.17 | E11: Septiembre'25 | S11: =P216 -> 0
E12: Octubre'25 | S12: =Q216 -> 0
B13: Total Recuperado | D13: =SUM(D6:D11) -> 581300.01 | E13: Noviembre'25 | S13: =R216 -> 0
B14: Por Recuperar | D14: =D2-D13 -> 45627.498 | E14: Total de Arrastre: | S14: =SUM(S2:S13) -> 50631.247
A16: NO. | B16: CLIENTE | C16: DATOS FISCALES | D16: CONTACTO | E16: UNI | F16: VENTA | G16: ATRASO | S16: IMPORTE MAR´2025 | T16: SERV. EXTRAS | U16: DES % | V16: 1 | W16: 2 | X16: 3 | Y16: 4 | Z16: 5 | AA16: 6 | AB16: 7 | AC16: 8 | AD16: 9 | AE16: 10 | AF16: 11 | AG16: 12 | AH16: 13 | AI16: 14 | AJ16: 15 | AK16: 16 | AL16: 17 | AM16: 18 | AN16: 19 | AO16: 20 | AP16: 21 | AQ16: 22 | AR16: 23 | AS16: 24 | AT16: 25 | AU16: 26 | AV16: 27 | AW16: 28 | AX16: 29 | AY16: 30 | AZ16: 31 | BA16: SALDOS PENDIENTES | BB16: COMENTARIOS | BC16: ESTATUS PROMESA DE PAGO
G17: 2024 | H17: ENE | I17: FEB | J17: MAR | K17: ABR | L17: MAY | M17: JUN | N17: JUL | O17: AGO | P17: SEP | Q17: OCT | R17: NOV | V17: S | W17: D | X17: L | Y17: M | Z17: M | AA17: J | AB17: V | AC17: S | AD17: D | AE17: L | AF17: M | AG17: M | AH17: J | AI17: V | AJ17: S | AK17: D | AL17: L | AM17: M | AN17: M | AO17: J | AP17: V | AQ17: S | AR17: D | AS17: L | AT17: M | AU17: M | AV17: J | AW17: V | AX17: S | AY17: D | AZ17: L
A18: 1 | B18: ADRIANA ORANDAY DAVILA - RODRIGO ALANIS | D18: Rodrigo Alanis - 81 2861 1509 Email:adrianaoranday@gmail.com alanis_rodrigo@hotmail.com | E18: 1 | F18: JOSE LUIS | G18: =[1]DICIEMBRE!$BA$91 -> 290 | H18: =ENERO!BA18 -> 580 | I18: =FEBRERO!AX18 -> 870 | S18: =(250*0.16+250)*E18 -> 290 | BA18: =SUM(I18+S18+T18-U18-V18-W18-X18-Y18-Z18-AA18-AB18-AC18-AD18-AE18-AF18-AG18-AH18-AI18-AJ18-AK18-AL18-AM18-AN18-AO18-AP18-AQ18-AR18-AS18-AT18-AU18-AV18-AW18-AX18-AY18-AZ18) -> 1160
A19: 2 | B19: ALIMENTOS REGIOMONTANOS PERCAM - ALIMENTOS GRUPER | C19: Nombre de la Empresa: ALIMENTOS GUPER S.A. DE C.V. Contacto: Nancy Paola Perales Teléfono: 811 801 4266 Email: alimentosgupersacv@gmail.com | D19: Alejandro Garcia - 81 2034 3938 Nancy Paola Perales - 8118014266 Alimentosregiopercam@gmail.com alimentosgupersacv@gmail.com | E19: 18 | F19: DANIEL ESTRADA | G19: =[1]DICIEMBRE!$BA$21 -> -0.3952 | H19: =ENERO!BA19 -> -0.3952 | I19: =FEBRERO!AX19 -> 0.0048 | S19: =(300*0.16+300)*E19 -> 6264 | T19: =500*0.16+500 -> 580 | Z19: 6844 | BA19: =SUM(I19+S19+T19-U19-V19-W19-X19-Y19-Z19-AA19-AB19-AC19-AD19-AE19-AF19-AG19-AH19-AI19-AJ19-AK19-AL19-AM19-AN19-AO19-AP19-AQ19-AR19-AS19-AT19-AU19-AV19-AW19-AX19-AY19-AZ19) -> 0.0048 | BB19: COB. MAR'25: 1 REVISION
A20: 3 | B20: AUTO EXPRESS GERAL 21 S.A. DE C.V. - LUIS GERARDO BOLAÑOS GARCIA | C20: Nombre de la Empresa: LUIS GERARDO BOLAÑOS GARCIA RFC. BOGL8702094H5 CFDI: Gastos en general Forma de Pago: Transferencia Teléfono: 811 027 0226 Contacto: Luis Gerardo Bolaños García Email: luismty0902@gmail.com; | D20: Luis Gerardo Bolaños García - 811 027 0226 Email:expressgeral19@gmail.com luismty0902@gmail.com | E20: 5 | F20: JOSE LUIS | G20: =[1]DICIEMBRE!$BA$75 -> 3190.0028 | H20: =ENERO!BA20 -> 0.0028 | I20: =FEBRERO!AX20 -> 0.0028 | S20: =(280*0.16+280)*E20 -> 1624 | AO20: 1624 | BA20: =SUM(I20+S20+T20-U20-V20-W20-X20-Y20-Z20-AA20-AB20-AC20-AD20-AE20-AF20-AG20-AH20-AI20-AJ20-AK20-AL20-AM20-AN20-AO20-AP20-AQ20-AR20-AS20-AT20-AU20-AV20-AW20-AX20-AY20-AZ20) -> 0.0028
A21: 4 | B21: AUTOEXPRESS MATA | C21: Nombre de la Empresa: AUTOEXPRESS MATA S.A. DE C.V. RFC. AMA040520BZ2 CFDI : Forma de Pago: Transferencia Teléfono: 81 1029 1017 Contacto: Edgar Garza Email: | D21: COMODATO Edgar Garza - 81 1029 1017 | E21: 4 | F21: JOSE LUIS | G21: =[1]DICIEMBRE!$BA$23 -> -0.0032 | H21: =ENERO!BA21 -> -0.0032 | I21: =FEBRERO!AX21 -> -0.0032 | S21: =(299*0.16+299)*E21 -> 1387.36 | T21: =500*0.16+500 -> 580 | AP21: 1967.36 | BA21: =SUM(I21+S21+T21-U21-V21-W21-X21-Y21-Z21-AA21-AB21-AC21-AD21-AE21-AF21-AG21-AH21-AI21-AJ21-AK21-AL21-AM21-AN21-AO21-AP21-AQ21-AR21-AS21-AT21-AU21-AV21-AW21-AX21-AY21-AZ21) -> -0.0032 | BB21: COB. MAR'25: 1 RECONFIGURACION DE EQUIPO Y CAMBIO DE SIM
A22: 5 | B22: AUTOREDES EL BAJIO | D22: COMODATO Mane Troncoso -833 192 6706 Email:admontubored@hotmail.com | E22: 10 | F22: JOSE LUIS | G22: =[1]DICIEMBRE!$BA$24 -> -0.3952 | H22: =ENERO!BA22 -> -0.3952 | I22: =FEBRERO!AX22 -> 0.0048 | S22: =(270*0.16+270)*E22 -> 3132 | X22: 3132 | BA22: =SUM(I22+S22+T22-U22-V22-W22-X22-Y22-Z22-AA22-AB22-AC22-AD22-AE22-AF22-AG22-AH22-AI22-AJ22-AK22-AL22-AM22-AN22-AO22-AP22-AQ22-AR22-AS22-AT22-AU22-AV22-AW22-AX22-AY22-AZ22) -> 0.0048
A23: 6 | B23: BAWOMA CONTROL TOTAL S.A. DE C.V. - FUMIGAZ | C23: Nombre de la Empresa: BAWOMA CONTROL TOTAL S.A. DE C.V. RFC.: BCT100310834 CFDI: Gastos en General Forma de Pago: Transferencia Teléfono: 81 1811 0645 Contacto: Manuel Rico Email: supervisorfumigaz@outlook.com | D23: COMODATO Manuel Rico - 81 1811 0645 Email:supervisorfumigaz@outlook.com | E23: 2 | F23: JOSE LUIS | G23: =[1]DICIEMBRE!$BA$48 -> 696 | H23: =ENERO!BA23 -> 696 | I23: =FEBRERO!AX23 -> 0 | S23: =(300*0.16+300)*1 -> 348 | AP23: 348 | BA23: =SUM(I23+S23+T23-U23-V23-W23-X23-Y23-Z23-AA23-AB23-AC23-AD23-AE23-AF23-AG23-AH23-AI23-AJ23-AK23-AL23-AM23-AN23-AO23-AP23-AQ23-AR23-AS23-AT23-AU23-AV23-AW23-AX23-AY23-AZ23) -> 0 | BB23: PDTE. 1 DES-INST. YA PAGADA
A24: 7 | B24: BE ONE SYSTEMS | D24: Lydia Colunga - 81 1176 3598 Edgar Valentin (Pagos) - 81 1970 7000 Email:edgar.valentin@beone.mx lydia@beone.mx | E24: 1 | F24: JOSE LUIS | G24: =[1]DICIEMBRE!$BA$25 -> 0 | H24: =ENERO!BA24 -> 0 | I24: =FEBRERO!AX24 -> 0 | S24: =250*0.16+250 -> 290 | X24: 290 | BA24: =SUM(I24+S24+T24-U24-V24-W24-X24-Y24-Z24-AA24-AB24-AC24-AD24-AE24-AF24-AG24-AH24-AI24-AJ24-AK24-AL24-AM24-AN24-AO24-AP24-AQ24-AR24-AS24-AT24-AU24-AV24-AW24-AX24-AY24-AZ24) -> 0
A25: 8 | B25: BRANDO IVAN MARTINEZ GOVEA - JOSUE FERNANDEZ | D25: Josue Fernandez - 81 1977 0958 Email:jfhz@icloud.com | E25: 5 | F25: JOSE LUIS | G25: =[1]DICIEMBRE!$BA$64 -> 0.0068 | H25: =ENERO!BA25 -> 0.0068 | I25: =FEBRERO!AX25 -> -0.0032 | S25: =(250*0.16+250)*E25 -> 1450 | AA25: 1450 | BA25: =SUM(I25+S25+T25-U25-V25-W25-X25-Y25-Z25-AA25-AB25-AC25-AD25-AE25-AF25-AG25-AH25-AI25-AJ25-AK25-AL25-AM25-AN25-AO25-AP25-AQ25-AR25-AS25-AT25-AU25-AV25-AW25-AX25-AY25-AZ25) -> -0.0032
A26: 9 | B26: CARLOS JONATHAN MARTINEZ RIVERA | D26: Jonathan Rivera - 81 1696 5321 jonathanrivera22929@gmail.com | E26: 1 | F26: JOSE LUIS | G26: =[1]DICIEMBRE!$BA$134 -> 0 | H26: =ENERO!BA139 -> 48 | I26: =FEBRERO!AX26 -> 0 | S26: =(300*0.16+300)*E26 -> 348 | Y26: 348 | BA26: =SUM(I26+S26+T26-U26-V26-W26-X26-Y26-Z26-AA26-AB26-AC26-AD26-AE26-AF26-AG26-AH26-AI26-AJ26-AK26-AL26-AM26-AN26-AO26-AP26-AQ26-AR26-AS26-AT26-AU26-AV26-AW26-AX26-AY26-AZ26) -> 0 | BB26: CAMBIA A ESQUEMA DE FACTURACION 05-FEBRERO-2025
A27: 10 | B27: CARNES RIBHAUS | D27: COMODATO Tania Reyes - 81 1631 2529 Roberta Treviño - 81 1909 7008 Email:facturas@carnesribhaus.com.mx robertaribhaus@gmail.com | E27: 5 | F27: JOSE LUIS | G27: =[1]DICIEMBRE!$BA$27 -> 0.004 | H27: =ENERO!BA26 -> 0.004 | I27: =FEBRERO!AX27 -> 0.004 | S27: =(279*0.16+279)*E27 -> 1618.2 | Y27: 1618.2 | BA27: =SUM(I27+S27+T27-U27-V27-W27-X27-Y27-Z27-AA27-AB27-AC27-AD27-AE27-AF27-AG27-AH27-AI27-AJ27-AK27-AL27-AM27-AN27-AO27-AP27-AQ27-AR27-AS27-AT27-AU27-AV27-AW27-AX27-AY27-AZ27) -> 0.004
A28: 11 | B28: CARPACK, S.A. DE C.V. | C28: Nombre de la Empresa: CARPACK S.A. DE C.V. RFC.: CAR070302UU2 CFDI: Gastos en General Forma de Pago: TransferenciaTeléfono: 811 277 9070 Contacto: Kelly Mayorga Email: compras@carpack.com.mx; antonioespinosa@carpack.com.mx; elizabeth@carpack.com.mx; | D28: COMODATO Kelly Mayorga - 8112779070 Elizabeth Campos - 8116635976 8181919205 Ext. 107 Email:antonioespinosa@carpack.com.mx; elizabeth@carpack.com.mx; compras@carpack.com.mx; pagos@carpack.com.mx | E28: 5 | F28: JOSE LUIS | G28: =[1]DICIEMBRE!$BA$28 -> 0.0028 | H28: =ENERO!BA27 -> 0.0028 | I28: =FEBRERO!AX28 -> 0.0028 | S28: =(280*0.16+280)*E28 -> 1624 | AA28: 1624 | BA28: =SUM(I28+S28+T28-U28-V28-W28-X28-Y28-Z28-AA28-AB28-AC28-AD28-AE28-AF28-AG28-AH28-AI28-AJ28-AK28-AL28-AM28-AN28-AO28-AP28-AQ28-AR28-AS28-AT28-AU28-AV28-AW28-AX28-AY28-AZ28) -> 0.0028
A29: 12 | B29: COMERCIALIZADORA AGROPECUARIA ICK -JORGE ADRIAN RIVERA | C29: Nombre de la Empresa: COMERCIALIZADORA AGROPECUARIA ICK S.A. DE C.V. RFC.: CAI220330VD7 CFDI: Gastos en general Teléfono: 81 2860 1814 Contacto: Adrian Rivera Email: adrian.rmoxica75@gmail.com | D29: COMODATO Adrian Rivera - 81 2860 1814 Email:adrian.rmoxica75@gmail.com | E29: 4 | F29: JOSE LUIS | G29: =[1]DICIEMBRE!$BA$20 -> 0 | H29: =ENERO!BA28 -> 0 | I29: =FEBRERO!AX29 -> 0 | S29: =(300*0.16+300)*E29 -> 1392 | Y29: 1392 | BA29: =SUM(I29+S29+T29-U29-V29-W29-X29-Y29-Z29-AA29-AB29-AC29-AD29-AE29-AF29-AG29-AH29-AI29-AJ29-AK29-AL29-AM29-AN29-AO29-AP29-AQ29-AR29-AS29-AT29-AU29-AV29-AW29-AX29-AY29-AZ29) -> 0
A30: 13 | B30: COMERCIALIZADORA FUERZA CEMENTERA | D30: Candy - 81 2634 9644 candymoreno@forzadelnorte.com | E30: 5 | F30: JOSE LUIS | G30: =[1]DICIEMBRE!$BA$31 -> -3480 | H30: =ENERO!BA29 -> -1740 | I30: =FEBRERO!AX30 -> 0 | S30: =(300*0.16+300)*E30 -> 1740 | AE30: 5220 | BA30: =SUM(I30+S30+T30-U30-V30-W30-X30-Y30-Z30-AA30-AB30-AC30-AD30-AE30-AF30-AG30-AH30-AI30-AJ30-AK30-AL30-AM30-AN30-AO30-AP30-AQ30-AR30-AS30-AT30-AU30-AV30-AW30-AX30-AY30-AZ30) -> -3480 | BB30: PAGO 3 MESES COBRAR HASTA JUNIO 2025
A31: 14 | B31: COMERCIALIZADORA Y LOGISTICA SIFAL - ARTURO SIFUENTES | D31: Arturo Sifuentes - 811 521 3582 Email: silvia-neri@hotmail.com; ventas@acertrans.com.mx; logisticasifal@hotmail.com; | E31: 5 | F31: JOSE LUIS | G31: =[1]DICIEMBRE!$BA$18 -> -128 | H31: =ENERO!BA30 -> -128 | I31: =FEBRERO!AX31 -> -128 | S31: =(350*0.16+350)*E31 -> 2030 | AO31: 2030 | BA31: =SUM(I31+S31+T31-U31-V31-W31-X31-Y31-Z31-AA31-AB31-AC31-AD31-AE31-AF31-AG31-AH31-AI31-AJ31-AK31-AL31-AM31-AN31-AO31-AP31-AQ31-AR31-AS31-AT31-AU31-AV31-AW31-AX31-AY31-AZ31) -> -128
A32: 15 | B32: COMPAÑÍA MADERERA CUAUHTEMOC | D32: COMODATO Daniel Cardenas - 81 2634 0402 Email:recepcionfacturas@ciamaderera.com | E32: 5 | F32: JOSE LUIS | G32: =[1]DICIEMBRE!$BA$77 -> 0.0012 | H32: =ENERO!BA31 -> 0.0012 | I32: =FEBRERO!AX32 -> 0.0012 | S32: =(250*0.16+250)*4+(300*0.16+300)*1 -> 1508 | Z32: 1508 | BA32: =SUM(I32+S32+T32-U32-V32-W32-X32-Y32-Z32-AA32-AB32-AC32-AD32-AE32-AF32-AG32-AH32-AI32-AJ32-AK32-AL32-AM32-AN32-AO32-AP32-AQ32-AR32-AS32-AT32-AU32-AV32-AW32-AX32-AY32-AZ32) -> 0.0012
A33: 16 | B33: CONTINENTAL PARABELLUM - GRUPO SAR | D33: Alan Rodriguez finanzas.gposar@gmail.com | E33: 6 | F33: MARIO ULISES | G33: =[1]DICIEMBRE!$BA$32 -> 0 | H33: =ENERO!BA32 -> -0.004 | I33: =FEBRERO!AX33 -> -0.004 | S33: =(279*0.16+279)*E33 -> 1941.84 | AF33: 1941.84 | BA33: =SUM(I33+S33+T33-U33-V33-W33-X33-Y33-Z33-AA33-AB33-AC33-AD33-AE33-AF33-AG33-AH33-AI33-AJ33-AK33-AL33-AM33-AN33-AO33-AP33-AQ33-AR33-AS33-AT33-AU33-AV33-AW33-AX33-AY33-AZ33) -> -0.004
A34: 17 | B34: DISTRIBUIDORA FERRELECTRICA Y MATERIALES EXPRESS - DEX MATERIALES | D34: Aleyda - 81 3402 1812 Rolando Ziragem 811 077 1470 812 597 2700 / 812 332 3606 oficina@dexmateriales.com; rzgc@hotmail.com; rolando@dexmateriales.com; | E34: 9 | F34: JOSE LUIS | G34: =[1]DICIEMBRE!$BA$34 -> 0 | H34: =ENERO!BA34 -> 0 | I34: =FEBRERO!AX35 -> 0 | S34: =(300*0.16+300)*E34 -> 3132 | AI34: 18792 | BA34: =SUM(I34+S34+T34-U34-V34-W34-X34-Y34-Z34-AA34-AB34-AC34-AD34-AE34-AF34-AG34-AH34-AI34-AJ34-AK34-AL34-AM34-AN34-AO34-AP34-AQ34-AR34-AS34-AT34-AU34-AV34-AW34-AX34-AY34-AZ34) -> -15660 | BB34: PAGARA 6 MENS. COBRAR HASTA EL MES DE SEPTIEMBRE 2025 CAMBIA A ESQUEMA DE MENSUALIDAD 06-SEPTIEMBRE-2024 Y DA DE BAJA 3 UNIDADES Y SE SEPARA CUENTA A COMERCIALIZADORA FUERZA CEMENTERA
A35: 18 | B35: EDGAR ALBERTO CORTEZ TREVIÑO | D35: Edgar Cortez - 81 8185 6454 | E35: 1 | F35: JOSE LUIS | G35: =[1]DICIEMBRE!$BA$35 -> 0 | H35: =ENERO!BA35 -> 0 | I35: =FEBRERO!AX36 -> 0 | S35: =(250*0.16+250)*E35 -> 290 | AB35: 290 | BA35: =SUM(I35+S35+T35-U35-V35-W35-X35-Y35-Z35-AA35-AB35-AC35-AD35-AE35-AF35-AG35-AH35-AI35-AJ35-AK35-AL35-AM35-AN35-AO35-AP35-AQ35-AR35-AS35-AT35-AU35-AV35-AW35-AX35-AY35-AZ35) -> 0
A36: 19 | B36: ELIZABETH RENTERIA REVILLA | C36: Nombre de la Empresa: ELIZABETH RENTERÍA REVILLA RFC. RERE760807SX9 CFDI: Gastos en general Forma de Pago: TransferenciaTeléfono: 811 810 0155 Contacto: Elizabeth Rentería Email: e.lic@live.com.mx | D36: Elizabeth Renteria - 811 810 0155 Email:e.lic@live.com.mx | E36: 2 | F36: JOSE LUIS | G36: =[1]DICIEMBRE!$BA$37 -> 0 | H36: =ENERO!BA36 -> 0 | I36: =FEBRERO!AX37 -> -0.0044 | S36: =(250*0.16+250)*E36 -> 580 | Y36: 580 | BA36: =SUM(I36+S36+T36-U36-V36-W36-X36-Y36-Z36-AA36-AB36-AC36-AD36-AE36-AF36-AG36-AH36-AI36-AJ36-AK36-AL36-AM36-AN36-AO36-AP36-AQ36-AR36-AS36-AT36-AU36-AV36-AW36-AX36-AY36-AZ36) -> -0.0044
A37: 20 | B37: ENDER INDUSTRIAL (EMMANUEL VAZQUEZ - SINERGIX ) | C37: Nombre de la Empresa: ENDER INDUSTRIAL S.A. DE C.V. RFC.: SIS1703089V6 CFDI: Gastos en General. Forma de Pago: Transferencia Teléfono: 813 055 7409 / 81) 2141 0506 Contacto: Emmanuel Vázquez / Sonia Lugo Email: emmanuel@sinergix.net; sonia@sinergix.net; | D37: COMODATO Emmanuel Vazquez - 81 3055 7409 Sonia Lugo (pagos) - 81 2141 0506 Email:sandra@enderindustrial.com claudia@enderindustrial.com belen@enderindustrial.com facturas@enderindustrial.com; emmanuel@sinergix.net; | E37: 7 | F37: JOSE LUIS | G37: =[1]DICIEMBRE!$BA$38 -> -753.9924 | H37: =ENERO!BA37 -> -753.9924 | I37: =FEBRERO!AX38 -> -753.9924 | S37: =(350*0.16+350)*E37 -> 2842 | AF37: 2842 | BA37: =SUM(I37+S37+T37-U37-V37-W37-X37-Y37-Z37-AA37-AB37-AC37-AD37-AE37-AF37-AG37-AH37-AI37-AJ37-AK37-AL37-AM37-AN37-AO37-AP37-AQ37-AR37-AS37-AT37-AU37-AV37-AW37-AX37-AY37-AZ37) -> -753.9924
A38: 21 | B38: ENDO LASER MICROQUIRURGICO - INSTITUTO VIDAURRI DE OJOS (DANIELA MEDELLIN) | D38: Daniela Medellín - 81 1588 8485 Email:monitoreo@endolaser.com.mx | E38: 4 | F38: JOSE LUIS | G38: =[1]DICIEMBRE!$BA$59 -> 6.8212103e-13 | H38: =ENERO!BA38 -> 9.094947e-13 | I38: =FEBRERO!AX39 -> 1.1368684e-12 | S38: =(249*0.16+249)*E38 -> 1155.36 | AE38: 1155.36 | BA38: =SUM(I38+S38+T38-U38-V38-W38-X38-Y38-Z38-AA38-AB38-AC38-AD38-AE38-AF38-AG38-AH38-AI38-AJ38-AK38-AL38-AM38-AN38-AO38-AP38-AQ38-AR38-AS38-AT38-AU38-AV38-AW38-AX38-AY38-AZ38) -> 1.3642421e-12
A39: 22 | B39: EXTINTORES Y EQUIPOS MONTERREY (SERGIO GONZALEZ) | D39: COMODATO Gabriela - 81 2077 4512 Sergio Gonzalez - 81 8654 2753 sergio.jr987@outlook.com | E39: 2 | F39: JOSE LUIS | G39: =[1]DICIEMBRE!$BA$41 -> 0 | H39: =ENERO!BA39 -> 0 | I39: =FEBRERO!AX40 -> 0 | S39: =(300*0.16+300)*2 -> 696 | AB39: 696 | BA39: =SUM(I39+S39+T39-U39-V39-W39-X39-Y39-Z39-AA39-AB39-AC39-AD39-AE39-AF39-AG39-AH39-AI39-AJ39-AK39-AL39-AM39-AN39-AO39-AP39-AQ39-AR39-AS39-AT39-AU39-AV39-AW39-AX39-AY39-AZ39) -> 0 | BB39: PDTE 1 INSTALACION YA PAGADA SOLO COBRAR PROP. CUANDO SE INSTALE
A40: 23 | B40: FERNANDO RAFAEL GONZALEZ MONTEMAYOR (SERVICIO DE PLATAFORMA) | C40: Nombre de la Empresa: GOMO SERVICES Contacto: FERNANDO DISATEL Email: frgm_76@hotmail.com Remisiones con IVA | D40: Fernando Disatel - 81 1799 2490 Email:frgm_76@hotmail.com | E40: 674 | F40: JOSE LUIS | G40: =[1]DICIEMBRE!$BA$42 -> 3220.026 | H40: =ENERO!BA40 -> 3220.026 | I40: =FEBRERO!AX41 -> 3220.028 | S40: =(38.8*0.16+38.8)*E40 -> 30335.392 | AT40: 30335.39 | BA40: =SUM(I40+S40+T40-U40-V40-W40-X40-Y40-Z40-AA40-AB40-AC40-AD40-AE40-AF40-AG40-AH40-AI40-AJ40-AK40-AL40-AM40-AN40-AO40-AP40-AQ40-AR40-AS40-AT40-AU40-AV40-AW40-AX40-AY40-AZ40) -> 3220.03
A41: 24 | B41: FERNANDO REYES HERNANDES | D41: COMODATO Fernando Reyes - 81 1821 3781 Viridiana Flores - 81 1796 4130 arnol84reyeshdz@gmail.com | E41: 1 | F41: JOSE LUIS | G41: =[1]DICIEMBRE!$BA$43 -> 348 | H41: =ENERO!BA41 -> 0 | I41: =FEBRERO!AX42 -> 0 | S41: =(300*0.16+300)*E41 -> 348 | AN41: 348 | BA41: =SUM(I41+S41+T41-U41-V41-W41-X41-Y41-Z41-AA41-AB41-AC41-AD41-AE41-AF41-AG41-AH41-AI41-AJ41-AK41-AL41-AM41-AN41-AO41-AP41-AQ41-AR41-AS41-AT41-AU41-AV41-AW41-AX41-AY41-AZ41) -> 0
A42: 25 | B42: FINPAIS | C42: Nombre de la Empresa: FINPAIS S.A. DE C.V. RFC. FCO130429629 CFDI: Gastos en general Forma de Pago: TransferenciaTeléfono: 81 8208 7559 Contacto: Katty Email: administracion@finpais.com.mx | D42: COMODATO Katty - 81 8208 7559 Email:administracion@finpais.com.mx | E42: 7 | F42: JOSE LUIS | G42: =[1]DICIEMBRE!$BA$44 -> 2598.3956 | H42: =ENERO!BA42 -> 5486.7956 | I42: =FEBRERO!AX43 -> 8085.1956 | S42: =(320*0.16+320)*E42 -> 2598.4 | BA42: =SUM(I42+S42+T42-U42-V42-W42-X42-Y42-Z42-AA42-AB42-AC42-AD42-AE42-AF42-AG42-AH42-AI42-AJ42-AK42-AL42-AM42-AN42-AO42-AP42-AQ42-AR42-AS42-AT42-AU42-AV42-AW42-AX42-AY42-AZ42) -> 10683.596
...

Sheet ABRIL
B2: Cobranza Total 2025 | D2: =SUM(S2+S3+S4+S5+S6+S7+S8+S9+S10+S11+S12+S13+D5) -> 579375.14 | E2: Saldos 2024 | S2: =G234 -> 26129.564
E3: Enero`25 | S3: =H234-S2 -> 13344.842
B4: COBRANZA ABRIL 2025 | E4: Febrero´25 | S4: =I234 -> -3120.3576
B5: ABRIL'2025 | D5: =S234+T234+U234 -> 538935.64 | E5: Marzo'25 | S5: =J234 -> 4085.4512
B6: Recuperación del 01 al 06 | D6: =SUM(V234:AA234) -> 118029.79 | E6: Abril´25 | S6: =K234 -> 0
B7: Recuperación del 07 al 13 | D7: =SUM(AB234:AH234) -> 100622.04 | E7: Mayo´25 | S7: =L234 -> 0
B8: Recuperación del 14 al 20 | D8: =SUM(AI234:AO234) -> 100082.12 | E8: Junio´25 | S8: =M234 -> 0
B9: Recuperación del 21 al 27 | D9: =SUM(AP234:AV234) -> 127665.74 | E9: Julio´25 | S9: =N234 -> 0
B10: Recuperación del 28 al 30 | D10: =SUM(AW234:AY234) -> 14638 | E10: Agosto'25 | S10: =O234 -> 0
E11: Septiembre'25 | S11: =P234 -> 0
E12: Octubre'25 | S12: =Q234 -> 0
B13: Total Recuperado | D13: =SUM(D6:D11) -> 461037.69 | E13: Noviembre'25 | S13: =R234 -> 0
B14: Por Recuperar | D14: =D2-D13 -> 118337.45 | E14: Total de Arrastre: | S14: =SUM(S2:S13) -> 40439.5
A16: NO. | B16: CLIENTE | C16: DATOS FISCALES | D16: CONTACTO | E16: UNI | F16: VENTA | G16: ATRASO | S16: IMPORTE ABRIL´2025 | T16: SERV. EXTRAS | U16: DES % | V16: 1 | W16: 2 | X16: 3 | Y16: 4 | Z16: 5 | AA16: 6 | AB16: 7 | AC16: 8 | AD16: 9 | AE16: 10 | AF16: 11 | AG16: 12 | AH16: 13 | AI16: 14 | AJ16: 15 | AK16: 16 | AL16: 17 | AM16: 18 | AN16: 19 | AO16: 20 | AP16: 21 | AQ16: 22 | AR16: 23 | AS16: 24 | AT16: 25 | AU16: 26 | AV16: 27 | AW16: 28 | AX16: 29 | AY16: 30 | AZ16: SALDOS PENDIENTES | BA16: COMENTARIOS | BB16: ESTATUS PROMESA DE PAGO
G17: 2024 | H17: ENE | I17: FEB | J17: MAR | K17: ABR | L17: MAY | M17: JUN | N17: JUL | O17: AGO | P17: SEP | Q17: OCT | R17: NOV | V17: M | W17: M | X17: J | Y17: V | Z17: S | AA17: D | AB17: L | AC17: M | AD17: M | AE17: J | AF17: V | AG17: S | AH17: D | AI17: L | AJ17: M | AK17: M | AL17: J | AM17: V | AN17: S | AO17: D | AP17: L | AQ17: M | AR17: M | AS17: J | AT17: V | AU17: S | AV17: D | AW17: L | AX17: M | AY17: M
A18: 1 | B18: ALIMENTOS REGIOMONTANOS PERCAM - ALIMENTOS GRUPER | C18: Nombre de la Empresa: ALIMENTOS GUPER S.A. DE C.V. Contacto: Nancy Paola Perales Teléfono: 811 801 4266 Email: alimentosgupersacv@gmail.com | D18: Alejandro Garcia - 81 2034 3938 Nancy Paola Perales - 8118014266 Alimentosregiopercam@gmail.com alimentosgupersacv@gmail.com | E18: 18 | F18: DANIEL ESTRADA | G18: =[1]DICIEMBRE!$BA$21 -> -0.3952 | H18: =ENERO!BA19 -> -0.3952 | I18: =FEBRERO!AX19 -> 0.0048 | J18: =MARZO!BA19 -> 0.0048 | S18: =(300*0.16+300)*E18 -> 6264 | T18: =500*0.16+500 -> 580 | W18: 6844 | AZ18: =SUM(J18+S18+T18-U18-V18-W18-X18-Y18-Z18-AA18-AB18-AC18-AD18-AE18-AF18-AG18-AH18-AI18-AJ18-AK18-AL18-AM18-AN18-AO18-AP18-AQ18-AR18-AS18-AT18-AU18-AV18-AW18-AX18-AY18) -> 0.0048 | BA18: COB. ABR'25: 1 REVISION
A19: 2 | B19: AUTO EXPRESS GERAL 21 S.A. DE C.V. - LUIS GERARDO BOLAÑOS GARCIA | C19: Nombre de la Empresa: LUIS GERARDO BOLAÑOS GARCIA RFC. BOGL8702094H5 CFDI: Gastos en general Forma de Pago: Transferencia Teléfono: 811 027 0226 Contacto: Luis Gerardo Bolaños García Email: luismty0902@gmail.com; | D19: Luis Gerardo Bolaños García - 811 027 0226 Email:expressgeral19@gmail.com luismty0902@gmail.com | E19: 5 | F19: JOSE LUIS | G19: =[1]DICIEMBRE!$BA$75 -> 3190.0028 | H19: =ENERO!BA20 -> 0.0028 | I19: =FEBRERO!AX20 -> 0.0028 | J19: =MARZO!BA20 -> 0.0028 | S19: =(280*0.16+280)*E19 -> 1624 | AE19: 1624 | AZ19: =SUM(J19+S19+T19-U19-V19-W19-X19-Y19-Z19-AA19-AB19-AC19-AD19-AE19-AF19-AG19-AH19-AI19-AJ19-AK19-AL19-AM19-AN19-AO19-AP19-AQ19-AR19-AS19-AT19-AU19-AV19-AW19-AX19-AY19) -> 0.0028
A20: 3 | B20: AUTOEXPRESS MATA | C20: Nombre de la Empresa: AUTOEXPRESS MATA S.A. DE C.V. RFC. AMA040520BZ2 CFDI : Forma de Pago: Transferencia Teléfono: 81 1029 1017 Contacto: Edgar Garza Email: | D20: COMODATO Edgar Garza - 81 1029 1017 Aexpresmata@gmail.com | E20: 4 | F20: JOSE LUIS | G20: =[1]DICIEMBRE!$BA$23 -> -0.0032 | H20: =ENERO!BA21 -> -0.0032 | I20: =FEBRERO!AX21 -> -0.0032 | J20: =MARZO!BA21 -> -0.0032 | S20: =(299*0.16+299)*E20 -> 1387.36 | AQ20: 1387.36 | AZ20: =SUM(J20+S20+T20-U20-V20-W20-X20-Y20-Z20-AA20-AB20-AC20-AD20-AE20-AF20-AG20-AH20-AI20-AJ20-AK20-AL20-AM20-AN20-AO20-AP20-AQ20-AR20-AS20-AT20-AU20-AV20-AW20-AX20-AY20) -> -0.0032
A21: 4 | B21: AUTOREDES EL BAJIO | D21: COMODATO Mane Troncoso -833 192 6706 Email:admontubored@hotmail.com | E21: 10 | F21: JOSE LUIS | G21: =[1]DICIEMBRE!$BA$24 -> -0.3952 | H21: =ENERO!BA22 -> -0.3952 | I21: =FEBRERO!AX22 -> 0.0048 | J21: =MARZO!BA22 -> 0.0048 | S21: =(270*0.16+270)*E21 -> 3132 | W21: 3132 | AZ21: =SUM(J21+S21+T21-U21-V21-W21-X21-Y21-Z21-AA21-AB21-AC21-AD21-AE21-AF21-AG21-AH21-AI21-AJ21-AK21-AL21-AM21-AN21-AO21-AP21-AQ21-AR21-AS21-AT21-AU21-AV21-AW21-AX21-AY21) -> 0.0048
A22: 5 | B22: BAWOMA CONTROL TOTAL S.A. DE C.V. - FUMIGAZ | C22: Nombre de la Empresa: BAWOMA CONTROL TOTAL S.A. DE C.V. RFC.: BCT100310834 CFDI: Gastos en General Forma de Pago: Transferencia Teléfono: 81 1811 0645 Contacto: Manuel Rico Email: supervisorfumigaz@outlook.com | D22: COMODATO Manuel Rico - 81 1811 0645 Email:supervisorfumigaz@outlook.com | E22: 2 | F22: JOSE LUIS | G22: =[1]DICIEMBRE!$BA$48 -> 696 | H22: =ENERO!BA23 -> 696 | I22: =FEBRERO!AX23 -> 0 | J22: =MARZO!BA23 -> 0 | S22: =(300*0.16+300)*1 -> 348 | AT22: 348 | AZ22: =SUM(J22+S22+T22-U22-V22-W22-X22-Y22-Z22-AA22-AB22-AC22-AD22-AE22-AF22-AG22-AH22-AI22-AJ22-AK22-AL22-AM22-AN22-AO22-AP22-AQ22-AR22-AS22-AT22-AU22-AV22-AW22-AX22-AY22) -> 0 | BA22: PDTE. 1 DES-INST. YA PAGADA
A23: 6 | B23: BE ONE SYSTEMS | D23: Lydia Colunga - 81 1176 3598 Edgar Valentin (Pagos) - 81 1970 7000 Email:edgar.valentin@beone.mx lydia@beone.mx | E23: 1 | F23: JOSE LUIS | G23: =[1]DICIEMBRE!$BA$25 -> 0 | H23: =ENERO!BA24 -> 0 | I23: =FEBRERO!AX24 -> 0 | J23: =MARZO!BA24 -> 0 | S23: =250*0.16+250 -> 290 | W23: 290 | AZ23: =SUM(J23+S23+T23-U23-V23-W23-X23-Y23-Z23-AA23-AB23-AC23-AD23-AE23-AF23-AG23-AH23-AI23-AJ23-AK23-AL23-AM23-AN23-AO23-AP23-AQ23-AR23-AS23-AT23-AU23-AV23-AW23-AX23-AY23) -> 0
A24: 7 | B24: BRANDO IVAN MARTINEZ GOVEA - JOSUE FERNANDEZ | D24: Josue Fernandez - 81 1977 0958 Email:jfhz@icloud.com | E24: 5 | F24: JOSE LUIS | G24: =[1]DICIEMBRE!$BA$64 -> 0.0068 | H24: =ENERO!BA25 -> 0.0068 | I24: =FEBRERO!AX25 -> -0.0032 | J24: =MARZO!BA25 -> -0.0032 | S24: =(250*0.16+250)*E24 -> 1450 | Y24: 1450 | AZ24: =SUM(J24+S24+T24-U24-V24-W24-X24-Y24-Z24-AA24-AB24-AC24-AD24-AE24-AF24-AG24-AH24-AI24-AJ24-AK24-AL24-AM24-AN24-AO24-AP24-AQ24-AR24-AS24-AT24-AU24-AV24-AW24-AX24-AY24) -> -0.0032
A25: 8 | B25: CARLOS JONATHAN MARTINEZ RIVERA | D25: Jonathan Rivera - 81 1696 5321 jonathanrivera22929@gmail.com | E25: 1 | F25: JOSE LUIS | G25: =[1]DICIEMBRE!$BA$134 -> 0 | H25: =ENERO!BA139 -> 48 | I25: =FEBRERO!AX26 -> 0 | J25: =MARZO!BA26 -> 0 | S25: =(300*0.16+300)*E25 -> 348 | AC25: 348 | AZ25: =SUM(J25+S25+T25-U25-V25-W25-X25-Y25-Z25-AA25-AB25-AC25-AD25-AE25-AF25-AG25-AH25-AI25-AJ25-AK25-AL25-AM25-AN25-AO25-AP25-AQ25-AR25-AS25-AT25-AU25-AV25-AW25-AX25-AY25) -> 0
A26: 9 | B26: CARNES RIBHAUS | D26: COMODATO Tania Reyes - 81 1631 2529 Roberta Treviño - 81 1909 7008 Email:facturas@carnesribhaus.com.mx robertaribhaus@gmail.com | E26: 5 | F26: JOSE LUIS | G26: =[1]DICIEMBRE!$BA$27 -> 0.004 | H26: =ENERO!BA26 -> 0.004 | I26: =FEBRERO!AX27 -> 0.004 | J26: =MARZO!BA27 -> 0.004 | S26: =(279*0.16+279)*E26 -> 1618.2 | X26: 1618.2 | AZ26: =SUM(J26+S26+T26-U26-V26-W26-X26-Y26-Z26-AA26-AB26-AC26-AD26-AE26-AF26-AG26-AH26-AI26-AJ26-AK26-AL26-AM26-AN26-AO26-AP26-AQ26-AR26-AS26-AT26-AU26-AV26-AW26-AX26-AY26) -> 0.004
A27: 10 | B27: CARPACK, S.A. DE C.V. | C27: Nombre de la Empresa: CARPACK S.A. DE C.V. RFC.: CAR070302UU2 CFDI: Gastos en General Forma de Pago: TransferenciaTeléfono: 811 277 9070 Contacto: Kelly Mayorga Email: compras@carpack.com.mx; antonioespinosa@carpack.com.mx; elizabeth@carpack.com.mx; | D27: COMODATO Kelly Mayorga - 8112779070 Elizabeth Campos - 8116635976 8181919205 Ext. 107 Email:antonioespinosa@carpack.com.mx; elizabeth@carpack.com.mx; compras@carpack.com.mx; pagos@carpack.com.mx | E27: 5 | F27: JOSE LUIS | G27: =[1]DICIEMBRE!$BA$28 -> 0.0028 | H27: =ENERO!BA27 -> 0.0028 | I27: =FEBRERO!AX28 -> 0.0028 | J27: =MARZO!BA28 -> 0.0028 | S27: =(280*0.16+280)*E27 -> 1624 | X27: 1624 | AZ27: =SUM(J27+S27+T27-U27-V27-W27-X27-Y27-Z27-AA27-AB27-AC27-AD27-AE27-AF27-AG27-AH27-AI27-AJ27-AK27-AL27-AM27-AN27-AO27-AP27-AQ27-AR27-AS27-AT27-AU27-AV27-AW27-AX27-AY27) -> 0.0028
A28: 11 | B28: COMERCIALIZADORA AGROPECUARIA ICK -JORGE ADRIAN RIVERA | C28: Nombre de la Empresa: COMERCIALIZADORA AGROPECUARIA ICK S.A. DE C.V. RFC.: CAI220330VD7 CFDI: Gastos en general Teléfono: 81 2860 1814 Contacto: Adrian Rivera Email: adrian.rmoxica75@gmail.com | D28: COMODATO Adrian Rivera - 81 2860 1814 Email:adrian.rmoxica75@gmail.com | E28: 4 | F28: JOSE LUIS | G28: =[1]DICIEMBRE!$BA$20 -> 0 | H28: =ENERO!BA28 -> 0 | I28: =FEBRERO!AX29 -> 0 | J28: =MARZO!BA29 -> 0 | S28: =(300*0.16+300)*E28 -> 1392 | X28: 1392 | AZ28: =SUM(J28+S28+T28-U28-V28-W28-X28-Y28-Z28-AA28-AB28-AC28-AD28-AE28-AF28-AG28-AH28-AI28-AJ28-AK28-AL28-AM28-AN28-AO28-AP28-AQ28-AR28-AS28-AT28-AU28-AV28-AW28-AX28-AY28) -> 0
A29: 12 | B29: COMERCIALIZADORA FUERZA CEMENTERA | D29: Candy - 81 2634 9644 candymoreno@forzadelnorte.com | E29: 5 | F29: JOSE LUIS | G29: =[1]DICIEMBRE!$BA$31 -> -3480 | H29: =ENERO!BA29 -> -1740 | I29: =FEBRERO!AX30 -> 0 | J29: =MARZO!BA30 -> -3480 | S29: =(300*0.16+300)*E29 -> 1740 | AZ29: =SUM(J29+S29+T29-U29-V29-W29-X29-Y29-Z29-AA29-AB29-AC29-AD29-AE29-AF29-AG29-AH29-AI29-AJ29-AK29-AL29-AM29-AN29-AO29-AP29-AQ29-AR29-AS29-AT29-AU29-AV29-AW29-AX29-AY29) -> -1740 | BA29: PAGO 3 MESES COBRAR HASTA JUNIO 2025
A30: 13 | B30: COMERCIALIZADORA Y LOGISTICA SIFAL - ARTURO SIFUENTES | D30: Arturo Sifuentes - 811 521 3582 Email: silvia-neri@hotmail.com; ventas@acertrans.com.mx; logisticasifal@hotmail.com; | E30: 5 | F30: JOSE LUIS | G30: =[1]DICIEMBRE!$BA$18 -> -128 | H30: =ENERO!BA30 -> -128 | I30: =FEBRERO!AX31 -> -128 | J30: =MARZO!BA31 -> -128 | S30: =(350*0.16+350)*E30 -> 2030 | AK30: 2030 | AZ30: =SUM(J30+S30+T30-U30-V30-W30-X30-Y30-Z30-AA30-AB30-AC30-AD30-AE30-AF30-AG30-AH30-AI30-AJ30-AK30-AL30-AM30-AN30-AO30-AP30-AQ30-AR30-AS30-AT30-AU30-AV30-AW30-AX30-AY30) -> -128
